r_bn:  0.01
lr:  0.25
Traceback (most recent call last):
  File "data_synthesis_new.py", line 367, in <module>
    bc, bc_weights = get_bary(args)
ValueError: too many values to unpack (expected 2)
=> using pytorch pre-trained model 'resnet18'
process data from ../recover/syn_data/imagenette/243
Traceback (most recent call last):
  File "generate_soft_label.py", line 256, in <module>
    main()
  File "generate_soft_label.py", line 129, in main
    main_worker(args.gpu, ngpus_per_node, args)
  File "generate_soft_label.py", line 201, in main_worker
    bary_weights_map = load_weights_file(args.data, os.path.join(args.data, 'barycenter_weights.txt'))
  File "/media/techt/One Touch/DD/SRe2L/relabel/utils_fkd.py", line 314, in load_weights_file
    with open(weight_path, 'r') as f:
FileNotFoundError: [Errno 2] No such file or directory: '../recover/syn_data/imagenette/243/barycenter_weights.txt'
W&B disabled.
W&B online. Running your script from this directory will now sync to the cloud.
wandb: Currently logged in as: hl57. Use `wandb login --relogin` to force relogin
wandb: wandb version 0.15.12 is available!  To upgrade, please run:
wandb:  $ pip install wandb --upgrade
wandb: Tracking run with wandb version 0.15.10
wandb: Run data is saved locally in /media/techt/One Touch/DD/SRe2L/train/wandb/run-20231012_233547-ejmp0bn9
wandb: Run `wandb offline` to turn off syncing.
wandb: Syncing run tough-firefly-409
wandb: ‚≠êÔ∏è View project at https://wandb.ai/hl57/final_rn18_fkd
wandb: üöÄ View run at https://wandb.ai/hl57/final_rn18_fkd/runs/ejmp0bn9
wandb: Waiting for W&B process to finish... (failed 1). Press Control-C to abort syncing.
wandb: üöÄ View run tough-firefly-409 at: https://wandb.ai/hl57/final_rn18_fkd/runs/ejmp0bn9
wandb: Ô∏è‚ö° View job at https://wandb.ai/hl57/final_rn18_fkd/jobs/QXJ0aWZhY3RDb2xsZWN0aW9uOjk3MzkyNjU3/version_details/v37
wandb: Synced 6 W&B file(s), 0 media file(s), 0 artifact file(s) and 0 other file(s)
wandb: Find logs at: ./wandb/run-20231012_233547-ejmp0bn9/logs
Traceback (most recent call last):
  File "train_FKD.py", line 398, in <module>
    main()
  File "train_FKD.py", line 102, in main
    assert os.path.exists(args.train_dir)
AssertionError
